<?xml version="1.0" encoding="utf-8"?>
<!DOCTYPE html PUBLIC "-//W3C//DTD XHTML 1.0 Strict//EN"
"http://www.w3.org/TR/xhtml1/DTD/xhtml1-strict.dtd">
<html xmlns="http://www.w3.org/1999/xhtml" lang="en" xml:lang="en">
<head>
<meta http-equiv="Content-Type" content="text/html;charset=utf-8" />
<meta name="viewport" content="width=device-width, initial-scale=1" />
<title>gunicorn spawn worker exception</title>
<meta name="author" content="dirtysalt" />
<meta name="generator" content="Org Mode" />
<link rel="shortcut icon" href="/themes/favicon.ico" /><link rel="stylesheet" type="text/css" href="/themes/simple.css"/></head>
<body>
<div id="content" class="content">
<h1 class="title">gunicorn spawn worker exception</h1>
<div id="table-of-contents" role="doc-toc">
<h2>Table of Contents</h2>
<div id="text-table-of-contents" role="doc-toc">
<ul>
<li><a href="#org435d62c">1. 事故现场</a></li>
<li><a href="#org8e31221">2. 事故分析</a></li>
</ul>
</div>
</div>

<div id="outline-container-org435d62c" class="outline-2">
<h2 id="org435d62c"><span class="section-number-2">1.</span> 事故现场</h2>
<div class="outline-text-2" id="text-1">
<p>
@2019-08-13T10:40:41
</p>

<p>
上周gunicorn事故，在其他webapp也出现了类似状况(push_rpc_server)。当时是data_rpc_server出现故障，但是日志里面没有具体原因
</p>

<div class="org-src-container">
<pre class="src src-Python">Traceback (most recent call last):
  File "src/gevent/greenlet.py", line 716, in gevent._greenlet.Greenlet.run
  File "/home/ec2-user/pulsar/venv/lib64/python3.6/dist-packages/gunicorn/arbiter.py", line 245, in handle_chld
    self.reap_workers()
  File "/home/ec2-user/pulsar/venv/lib64/python3.6/dist-packages/gunicorn/arbiter.py", line 525, in reap_workers
    raise HaltServer(reason, self.WORKER_BOOT_ERROR)
gunicorn.errors.HaltServer: &lt;HaltServer 'Worker failed to boot.' 3&gt;
2019-08-06T05:53:55Z &lt;Greenlet "Greenlet-0" at 0x7efd3483ca48: &lt;bound method Arbiter.handle_chld of &lt;gunicorn.arbiter.Arbiter object at 0x7efd34746978&gt;&gt;(17, None)&gt; failed with HaltServer
</pre>
</div>

<p>
然后今天 push_rpc_server 也出现类似故障，但是保存了错误日志
</p>

<div class="org-src-container">
<pre class="src src-Python">[2019-08-12 07:09:52 +0000] [45142] [ERROR] Exception in worker process
Traceback (most recent call last):
  File "/home/ec2-user/pulsar/venv/lib64/python3.6/dist-packages/gunicorn/arbiter.py", line 583, in spawn_worker
    worker.init_process()
  File "/home/ec2-user/pulsar/venv/lib64/python3.6/dist-packages/gunicorn/workers/ggevent.py", line 203, in init_process
    super(GeventWorker, self).init_process()
  File "/home/ec2-user/pulsar/venv/lib64/python3.6/dist-packages/gunicorn/workers/base.py", line 129, in init_process
    self.load_wsgi()
  File "/home/ec2-user/pulsar/venv/lib64/python3.6/dist-packages/gunicorn/workers/base.py", line 138, in load_wsgi
    self.wsgi = self.app.wsgi()
  File "/home/ec2-user/pulsar/venv/lib64/python3.6/dist-packages/gunicorn/app/base.py", line 67, in wsgi
    self.callable = self.load()
  File "/home/ec2-user/pulsar/venv/lib64/python3.6/dist-packages/gunicorn/app/wsgiapp.py", line 52, in load
    return self.load_wsgiapp()
  File "/home/ec2-user/pulsar/venv/lib64/python3.6/dist-packages/gunicorn/app/wsgiapp.py", line 41, in load_wsgiapp
    return util.import_app(self.app_uri)
  File "/home/ec2-user/pulsar/venv/lib64/python3.6/dist-packages/gunicorn/util.py", line 350, in import_app
    __import__(module)
  File "/home/ec2-user/pulsar/push/webapp/app.py", line 8, in &lt;module&gt;
    from push.webapp import ops_app
  .....
  File "/home/ec2-user/pulsar/core/ext/net_ext.py", line 23, in HttpProxyList
    def get(self, region, request_region=config.APP_RUNNING_REGION, stats=None, raw_docs=None):
AttributeError: module 'config' has no attribute 'APP_RUNNING_REGION'
</pre>
</div>

<p>
从这个错误日志看出现了加载模块的错误 config 里面增加属性 APP_RUNNING_REGION. 但是当时我的操作只是更新代码，而没有进行重启。下面可以看到push_rpc_server一直在运行。
</p>

<pre class="example" id="org38b5a13">
[ec2-user@host pulsar]$ supervisorctl
push_rpc_server                  RUNNING   pid 37526, uptime 28 days, 8:28:01
</pre>
</div>
</div>

<div id="outline-container-org8e31221" class="outline-2">
<h2 id="org8e31221"><span class="section-number-2">2.</span> 事故分析</h2>
<div class="outline-text-2" id="text-2">
<p>
这个和gunicorn运行机制有关系：
</p>

<ol class="org-ol">
<li>gunicorn master首先会fork出多个workers</li>
<li>worker处理一定请求之后，gunicorn会reap掉某个worker</li>
<li>然后spwan worker保持worker数量</li>
</ol>

<p>
spawn worker是通过os.fork来实现的，worker里面得到的是app对象(app.wsgiapp.WSGIApplication)。这个app对象并没有load python code(gunicorn.util.import_app), 当在执行之前才会load(load_wsgiapp). 所以如果在worker里面load python code失败的话，那么就会一直出现这个错误。
</p>

<p>
如果代码保持不变的话，那么load python code应该是不会失败的。但是如果期间发生代码变化的话，那么可能就会出现错误。TODO(yan): 现在还没有找到可以简单复现的例子，但是从stacktrace来看，的确是因为访问模块不存在的属性导致的。
</p>

<p>
gunicorn上面有个选项是 `&#x2013;preload` 这个选项是在第一次启动的时候就把python code全部import上来，之后所有的worker都直接使用这个wsgi对象，不再会触发load python code逻辑。
</p>

<div class="org-src-container">
<pre class="src src-Python"># class Arbiter(object):
def setup(self, app):
   ...
   if self.cfg.preload_app:
       self.app.wsgi() # 这里会触发import逻辑

# class Worker(object)
def init_process(self): # worker里面初始化逻辑
    ...
    self.load_wsgi()
    self.cfg.post_worker_init(self)

# class BaseApplication(object):
def wsgi(self):
    if self.callable is None:
        self.callable = self.load()
    return self.callable
</pre>
</div>

<p>
使用这种方式可以保证在整个运行期间，整个worker使用的code不再会变化。
</p>
</div>
</div>
</div>
</body>
</html>
